Workbook

Sheet Pulping
A1: Biomass | B1: Code | C1: Pulping | D1: Chemical_charge | E1: Liquor_Biomass_ratio | F1: pH | G1: Temperature | H1: Time_at_max_T | I1: Raw_material_OD | J1: Total_pulp_OD | K1: Total_yield | L1: Screened_mass | M1: Screening_yield | N1: Total_screened_yield | O1: Kappa
A2: W | B2: W1 | C2: Ammonium bisulfite | D2: 0.25 | E2: 6 | F2: 5.5 | G2: 150 | H2: 7 | I2: 240 | J2: =417.36*26.43% -> 110.30825 | K2: =J2/I2 -> 0.4596177 | L2: =357.8*0.28 -> 100.184 | M2: =L2/J2 -> 0.90821858 | N2: =L2/I2 -> 0.41743333 | O2: 12
A3: W | B3: W2 | C3: Ammonium bisulfite | D3: 0.25 | E3: 6 | F3: 5.5 | G3: 150 | H3: 7 | I3: 240 | J3: =419.4*0.2604 -> 109.21176 | K3: =J3/I3 -> 0.455049 | L3: =349.71*0.2962 -> 103.5841 | M3: =L3/J3 -> 0.94847022 | N3: =L3/I3 -> 0.43160043 | O3: 13.1
A4: W | B4: W3 | C4: Ammonium bisulfite | D4: 0.25 | E4: 6 | F4: 5.5 | G4: 150 | H4: 7 | I4: 240 | J4: =419.3*0.26 -> 109.018 | K4: =J4/I4 -> 0.45424167 | L4: =346.42*0.299 -> 103.57958 | M4: =L4/J4 -> 0.95011448 | N4: =L4/I4 -> 0.43158158 | O4: 12.6
A5: E | B5: E1 | C5: Ammonium bisulfite | D5: 0.25 | E5: 4 | F5: 5.5 | G5: 160 | H5: 6.25 | I5: 250 | J5: =389.41*0.3049 -> 118.73111 | K5: =J5/I5 -> 0.47492444 | L5: =342.76*0.3051 -> 104.57608 | M5: =L5/J5 -> 0.88078076 | N5: =L5/I5 -> 0.4183043 | O5: 13.4
A6: E | B6: E2 | C6: Ammonium bisulfite | D6: 0.25 | E6: 4 | F6: 5.5 | G6: 160 | H6: 6.25 | I6: 250 | J6: =400.59*0.3052 -> 122.26007 | K6: =J6/I6 -> 0.48904027 | L6: =353.84*0.2996 -> 106.01046 | M6: =L6/J6 -> 0.86708985 | N6: =L6/I6 -> 0.42404186 | O6: 13.3
A7: E | B7: E3 | C7: Ammonium bisulfite | D7: 0.25 | E7: 4 | F7: 5.5 | G7: 160 | H7: 6.25 | I7: 250 | J7: =386.03*0.3052 -> 117.81636 | K7: =J7/I7 -> 0.47126542 | L7: =328.98*0.3052 -> 100.4047 | M7: =L7/J7 -> 0.85221356 | N7: =L7/I7 -> 0.40161878 | O7: 14.7

Sheet Fines_removal
C1: Whole Pulp | I1: Fines Free
B2: Code | C2: Total wet weight | D2: Consistency | E2: Total Dry weight | F2: For classifier | G2: Per batch | H2: Dry weigh for handsheets | I2: Wet weight | J2: Consistency | K2: Dry weight | L2: Classifcation yield
B3: W1 | C3: 330.24 | D3: 0.2836 | E3: =C3*D3 -> 93.656064 | F3: =C3/2 -> 165.12 | G3: =F3/4 -> 41.28 | H3: =E3/2 -> 46.828032 | I3: =117.84-3.54 -> 114.3 | J3: 0.281 | K3: =I3*J3 -> 32.1183 | L3: =K3/(F3*D3) -> 0.68587764
B4: W2 | C4: 323 | D4: 0.2962 | E4: =C4*D4 -> 95.6726 | F4: =C4/2 -> 161.5 | G4: =F4/4 -> 40.375 | H4: =E4/2 -> 47.8363 | I4: =120.39-3.58 -> 116.81 | J4: 0.309 | K4: =I4*J4 -> 36.09429 | L4: =K4/(F4*D4) -> 0.75453766
B5: W3 | C5: 319.8 | D5: 0.299 | E5: =C5*D5 -> 95.6202 | F5: =C5/2 -> 159.9 | G5: =F5/4 -> 39.975 | H5: =E5/2-10 -> 37.8101 | I5: =118.86-3.59 -> 115.27 | J5: 0.2778 | K5: =I5*J5 -> 32.022006 | L5: =K5/(F5*D5) -> 0.66977492 | N5: 33.51 gr wet more because spill of one batch
B6: E1 | C6: =328.62-9.1 -> 319.52 | D6: 0.3051 | E6: =C6*D6 -> 97.485552 | F6: =C6/2 -> 159.76 | G6: =F6/4 -> 39.94 | H6: =E6/2 -> 48.742776 | I6: =120.22-3.71 -> 116.51 | J6: 0.2812 | K6: =I6*J6 -> 32.762612 | L6: =K6/(F6*D6) -> 0.67215318
B7: E2 | C7: =332.89-9.03 -> 323.86 | D7: 0.2996 | E7: =C7*D7 -> 97.028456 | F7: =C7/2 -> 161.93 | G7: =F7/4 -> 40.4825 | H7: =E7/2 -> 48.514228 | I7: 100.95 | J7: 0.2922 | K7: =I7*J7 -> 29.49759 | L7: =K7/(F7*D7) -> 0.60801936
B8: E3 | C8: =316.64-9.02 -> 307.62 | D8: 0.3052 | E8: =C8*D8 -> 93.885624 | F8: =C8/2 -> 153.81 | G8: =F8/4 -> 38.4525 | H8: =E8/2 -> 46.942812 | I8: 104.03 | J8: 0.2959 | K8: =I8*J8 -> 30.782477 | L8: =K8/(F8*D8) -> 0.65574421

Sheet Handsheets_making
B2: Sample | C2: Treatment 1 | D2: Treatment 2 | E2: ID | F2: Basis weight (target) | G2: Mass per Handsheet | H2: Handsheets per treatment | I2: Total mass | J2: Total | K2: Consistency | L2: Wet weight | M2: To dsisintegrate | N2: Final volume | P2: Freeness | Q2: Temp | R2: OD mass freeness HS | S2: Consistency | T2: Corrected Freeness | U2: Volume for Handsheets
B3: W1 | C3: Standard | D3: Fines | E3: W1F | F3: 60 | G3: =F3*0.02 -> 1.2 | H3: 4 | I3: =H3*G3 -> 4.8 | J3: =IFERROR(I3*5+3, " ") -> 27 | K3: =Fines_removal!D3 -> 0.2836 | L3: =IFERROR(J3/K3," ") -> 95.204513 | M3: =IFERROR(J3/0.012, " ") -> 2250 | N3: 9055 | O3: =J3/N3 -> 0.002981778 | P3: 500 | Q3: 28 | R3: 2.967 | S3: =R3/1000 -> 0.002967 | U3: =1.2/S3 -> 404.44894
B4: W1 | C4: Recirculation | D4: Fines | E4: W1F | F4: 60 | G4: =F4*0.02 -> 1.2 | H4: 4 | I4: =H4*G4 -> 4.8 | L4: =IFERROR(J4/K4," ")
B5: W1 | C5: Additive | D5: Fines | E5: W1AF | F5: 60 | G5: =F5*0.02 -> 1.2 | H5: 4 | I5: =H5*G5 -> 4.8 | J5: =I5 -> 4.8 | K5: =K3 -> 0.2836 | L5: =IFERROR(J5/K5," ") -> 16.925247 | M5: =IFERROR(J5/0.012, " ") -> 400 | N5: =J5/0.003 -> 1600
B6: W1 | C6: Standard | D6: No Fines | E6: W1SN | F6: 60 | G6: =F6*0.02 -> 1.2 | H6: 4 | I6: =H6*G6 -> 4.8 | J6: =I6*5+3 -> 27 | K6: =Fines_removal!J3 -> 0.281 | L6: =IFERROR(J6/K6," ") -> 96.085409 | M6: 2250 | N6: 9008 | O6: =J6/N6 -> 0.0029973357 | P6: 600 | Q6: 29 | R6: 2.97 | S6: =R6/1000 -> 0.00297 | U6: =1.2/S6 -> 404.0404
B7: W1 | C7: Recirculation | D7: No Fines | E7: W1RN | F7: 60 | G7: =F7*0.02 -> 1.2 | H7: 4 | I7: =H7*G7 -> 4.8 | L7: =IFERROR(J7/K7," ")
B8: W1 | C8: Additive | D8: No Fines | E8: W1AN | F8: 60 | G8: =F8*0.02 -> 1.2 | H8: 4 | I8: =H8*G8 -> 4.8 | J8: =I8 -> 4.8 | K8: =K6 -> 0.281 | L8: =IFERROR(J8/K8," ") -> 17.081851 | M8: =IFERROR(J8/0.012, " ") -> 400
B9: W2 | C9: Standard | D9: Fines | E9: W2SF | F9: 60 | G9: =F9*0.02 -> 1.2 | H9: 4 | I9: =H9*G9 -> 4.8 | J9: =I9*5+3 -> 27 | K9: =Fines_removal!D4 -> 0.2962 | L9: =IFERROR(J9/K9," ") -> 91.154625 | M9: 2250 | N9: 9031 | O9: =J9/N9 -> 0.0029897021 | P9: 510 | Q9: 28 | R9: 3.08 | S9: =R9/1000 -> 0.00308 | U9: =1.2/S9 -> 389.61039
B10: W2 | C10: Recirculation | D10: Fines | E10: W2RF | F10: 60 | G10: =F10*0.02 -> 1.2 | H10: 4 | I10: =H10*G10 -> 4.8 | L10: =IFERROR(J10/K10," ")
B11: W2 | C11: Additive | D11: Fines | E11: W2AF | F11: 60 | G11: =F11*0.02 -> 1.2 | H11: 4 | I11: =H11*G11 -> 4.8 | J11: =I11 -> 4.8 | K11: =K9 -> 0.2962 | L11: =IFERROR(J11/K11," ") -> 16.205267 | M11: =IFERROR(J11/0.012, " ") -> 400
B12: W2 | C12: Standard | D12: No Fines | E12: W2SN | F12: 60 | G12: =F12*0.02 -> 1.2 | H12: 4 | I12: =H12*G12 -> 4.8 | J12: =I12*5+3 -> 27 | K12: =Fines_removal!J4 -> 0.309 | L12: =IFERROR(J12/K12," ") -> 87.378641 | M12: 2250 | N12: 9019 | O12: =J12/N12 -> 0.00299368 | P12: 620 | Q12: 30 | R12: 2.767 | S12: =R12/1000 -> 0.002767 | U12: =1.2/S12 -> 433.68269
B13: W2 | C13: Recirculation | D13: No Fines | E13: W2RN | F13: 60 | G13: =F13*0.02 -> 1.2 | H13: 4 | I13: =H13*G13 -> 4.8 | L13: =IFERROR(J13/K13," ") | S13: =8000/U3 -> 19.78
B14: W2 | C14: Additive | D14: No Fines | E14: W2AN | F14: 60 | G14: =F14*0.02 -> 1.2 | H14: 4 | I14: =H14*G14 -> 4.8 | J14: =I14 -> 4.8 | K14: =K12 -> 0.309 | L14: =IFERROR(J14/K14," ") -> 15.533981 | M14: =IFERROR(J14/0.012, " ") -> 400
B15: W3 | C15: Standard | D15: Fines | E15: W3SF | F15: 60 | G15: =F15*0.02 -> 1.2 | H15: 4 | I15: =H15*G15 -> 4.8 | J15: =I15*5+3 -> 27 | K15: =Fines_removal!D5 -> 0.299 | L15: =IFERROR(J15/K15," ") -> 90.301003 | M15: 2250 | N15: 9030 | O15: =J15/N15 -> 0.0029900332 | P15: 500 | Q15: 28 | R15: 3.067 | S15: =R15/1000 -> 0.003067 | U15: =1.2/S15 -> 391.26182
B16: W3 | C16: Recirculation | D16: Fines | E16: W3RF | F16: 60 | G16: =F16*0.02 -> 1.2 | H16: 4 | I16: =H16*G16 -> 4.8 | L16: =IFERROR(J16/K16," ")
B17: W3 | C17: Additive | D17: Fines | E17: W3AF | F17: 60 | G17: =F17*0.02 -> 1.2 | H17: 4 | I17: =H17*G17 -> 4.8 | J17: =I17 -> 4.8 | K17: =K15 -> 0.299 | L17: =IFERROR(J17/K17," ") -> 16.053512 | M17: =IFERROR(J17/0.012, " ") -> 400
B18: W3 | C18: Standard | D18: No Fines | E18: W3SN | F18: 60 | G18: =F18*0.02 -> 1.2 | H18: 4 | I18: =H18*G18 -> 4.8 | J18: =I18*5+3 -> 27 | K18: =Fines_removal!J5 -> 0.2778 | L18: =IFERROR(J18/K18," ") -> 97.192225 | M18: 2250 | N18: 9240 | O18: =J18/N18 -> 0.0029220779 | P18: 600 | Q18: 29 | R18: 2.994 | S18: =R18/1000 -> 0.002994 | U18: =1.2/S18 -> 400.8016
B19: W3 | C19: Recirculation | D19: No Fines | E19: W3RN | F19: 60 | G19: =F19*0.02 -> 1.2 | H19: 4 | I19: =H19*G19 -> 4.8 | L19: =IFERROR(J19/K19," ")
B20: W3 | C20: Additive | D20: No Fines | E20: W3AN | F20: 60 | G20: =F20*0.02 -> 1.2 | H20: 4 | I20: =H20*G20 -> 4.8 | J20: =I20 -> 4.8 | K20: =K18 -> 0.2778 | L20: =IFERROR(J20/K20," ") -> 17.278618 | M20: =IFERROR(J20/0.012, " ") -> 400
B21: E1 | C21: Standard | D21: Fines | E21: E1SF | F21: 60 | G21: =F21*0.02 -> 1.2 | H21: 4 | I21: =H21*G21 -> 4.8 | J21: =I21*5+3 -> 27 | K21: =Fines_removal!D6 -> 0.3051 | L21: =IFERROR(J21/K21," ") -> 88.495575 | M21: 2250 | N21: 9004 | O21: =J21/N21 -> 0.0029986673 | P21: 600 | Q21: 28 | R21: 3.094 | S21: =R21/1000 -> 0.003094 | U21: =1.2/S21 -> 387.84745
B22: E1 | C22: Recirculation | D22: Fines | E22: E1RF | F22: 60 | G22: =F22*0.02 -> 1.2 | H22: 4 | I22: =H22*G22 -> 4.8 | L22: =IFERROR(J22/K22," ")
B23: E1 | C23: Additive | D23: Fines | E23: E1AF | F23: 60 | G23: =F23*0.02 -> 1.2 | H23: 4 | I23: =H23*G23 -> 4.8 | J23: =I23 -> 4.8 | K23: =K21 -> 0.3051 | L23: =IFERROR(J23/K23," ") -> 15.732547 | M23: =IFERROR(J23/0.012, " ") -> 400
B24: E1 | C24: Standard | D24: No Fines | E24: E1SN | F24: 60 | G24: =F24*0.02 -> 1.2 | H24: 4 | I24: =H24*G24 -> 4.8 | J24: =I24*5+3 -> 27 | K24: =Fines_removal!J6 -> 0.2812 | L24: =IFERROR(J24/K24," ") -> 96.01707 | M24: 2250 | N24: 9069 | O24: =J24/N24 -> 0.002977175 | P24: 670 | Q24: 30 | R24: 2.872 | S24: =R24/1000 -> 0.002872 | U24: =1.2/S24 -> 417.8273
B25: E1 | C25: Recirculation | D25: No Fines | E25: E1RN | F25: 60 | G25: =F25*0.02 -> 1.2 | H25: 4 | I25: =H25*G25 -> 4.8 | L25: =IFERROR(J25/K25," ")
B26: E1 | C26: Additive | D26: No Fines | E26: E1AN | F26: 60 | G26: =F26*0.02 -> 1.2 | H26: 4 | I26: =H26*G26 -> 4.8 | J26: =I26 -> 4.8 | K26: =K24 -> 0.2812 | L26: =IFERROR(J26/K26," ") -> 17.069701 | M26: =IFERROR(J26/0.012, " ") -> 400
B27: E2 | C27: Standard | D27: Fines | E27: E2SF | F27: 60 | G27: =F27*0.02 -> 1.2 | H27: 4 | I27: =H27*G27 -> 4.8 | J27: =I27*5+3 -> 27 | K27: =Fines_removal!D7 -> 0.2996 | L27: =IFERROR(J27/K27," ") -> 90.12016 | M27: 2250 | N27: 9022 | O27: =J27/N27 -> 0.0029926845 | P27: 610 | Q27: 30 | R27: 3.075 | S27: =R27/1000 -> 0.003075 | U27: =1.2/S27 -> 390.2439
B28: E2 | C28: Recirculation | D28: Fines | E28: E2RF | F28: 60 | G28: =F28*0.02 -> 1.2 | H28: 4 | I28: =H28*G28 -> 4.8 | L28: =IFERROR(J28/K28," ")
B29: E2 | C29: Additive | D29: Fines | E29: E2AF | F29: 60 | G29: =F29*0.02 -> 1.2 | H29: 4 | I29: =H29*G29 -> 4.8 | J29: =I29 -> 4.8 | K29: =K27 -> 0.2996 | L29: =IFERROR(J29/K29," ") -> 16.021362 | M29: =IFERROR(J29/0.012, " ") -> 400
B30: E2 | C30: Standard | D30: No Fines | E30: E2SN | F30: 60 | G30: =F30*0.02 -> 1.2 | H30: 4 | I30: =H30*G30 -> 4.8 | J30: =I30*5+3 -> 27 | K30: =Fines_removal!J7 -> 0.2922 | L30: =IFERROR(J30/K30," ") -> 92.402464 | M30: 2250 | N30: 8984 | O30: =J30/N30 -> 0.0030053428 | P30: 690 | Q30: 31 | R30: 2.706 | S30: =R30/1000 -> 0.002706 | U30: =1.2/S30 -> 443.45898
B31: E2 | C31: Recirculation | D31: No Fines | E31: E2RN | F31: 60 | G31: =F31*0.02 -> 1.2 | H31: 4 | I31: =H31*G31 -> 4.8 | L31: =IFERROR(J31/K31," ")
B32: E2 | C32: Additive | D32: No Fines | E32: E2AN | F32: 60 | G32: =F32*0.02 -> 1.2 | H32: 4 | I32: =H32*G32 -> 4.8 | J32: =I32 -> 4.8 | K32: =K30 -> 0.2922 | L32: =IFERROR(J32/K32," ") -> 16.427105 | M32: =IFERROR(J32/0.012, " ") -> 400
B33: E3 | C33: Standard | D33: Fines | E33: E3SF | F33: 60 | G33: =F33*0.02 -> 1.2 | H33: 4 | I33: =H33*G33 -> 4.8 | J33: =I33*5+3 -> 27 | K33: =Fines_removal!D8 -> 0.3052 | L33: =IFERROR(J33/K33," ") -> 88.466579 | M33: 2250 | N33: 9037 | O33: =J33/N33 -> 0.0029877172 | P33: 630 | Q33: 30 | R33: 3.143 | S33: =R33/1000 -> 0.003143 | U33: =1.2/S33 -> 381.80083
B34: E3 | C34: Recirculation | D34: Fines | E34: E3RF | F34: 60 | G34: =F34*0.02 -> 1.2 | H34: 4 | I34: =H34*G34 -> 4.8 | L34: =IFERROR(J34/K34," ")
B35: E3 | C35: Additive | D35: Fines | E35: E3AF | F35: 60 | G35: =F35*0.02 -> 1.2 | H35: 4 | I35: =H35*G35 -> 4.8 | J35: =I35 -> 4.8 | K35: =K33 -> 0.3052 | L35: =IFERROR(J35/K35," ") -> 15.727392 | M35: =IFERROR(J35/0.012, " ") -> 400
B36: E3 | C36: Standard | D36: No Fines | E36: E3SN | F36: 60 | G36: =F36*0.02 -> 1.2 | H36: 4 | I36: =H36*G36 -> 4.8 | J36: =I36*5+3 -> 27 | K36: =Fines_removal!J8 -> 0.2959 | L36: =IFERROR(J36/K36," ") -> 91.247043 | M36: 2250 | N36: 8978 | O36: =J36/N36 -> 0.0030073513 | P36: 685 | Q36: 30 | R36: 2.805 | S36: =R36/1000 -> 0.002805 | U36: =1.2/S36 -> 427.80749
B37: E3 | C37: Recirculation | D37: No Fines | E37: E3RN | F37: 60 | G37: =F37*0.02 -> 1.2 | H37: 4 | I37: =H37*G37 -> 4.8 | L37: =IFERROR(J37/K37," ")
B38: E3 | C38: Additive | D38: No Fines | E38: E3AN | F38: 60 | G38: =F38*0.02 -> 1.2 | H38: 4 | I38: =H38*G38 -> 4.8 | J38: =I38 -> 4.8 | K38: =K36 -> 0.2959 | L38: =IFERROR(J38/K38," ") -> 16.221697 | M38: =IFERROR(J38/0.012, " ") -> 400
I39: =SUM(I3:I35) -> 158.4
B40: Additive handsheets
B41: Mass per sheet | C41: =G5 -> 1.2 | D41: g fiber
...

Sheet FQA
C1: Consistency | D1: Dry weight | E1: Dilution | F1: Concentration | G1: Volumen to FQA (1) | H1: Dry mass to FQA (1) | I1: Volumen to FQA (2) | J1: Dry mass to FQA (2)
A2: Code | B2: Wet weight | C2: =AVERAGE(0.2734, 0.2829, 0.2827) -> 0.27966667 | D2: =C2*B3 -> 0.025897133 | E2: 5014.9 | F2: =D2/E2 -> 5.1640378e-06 | G2: 428.4 | H2: =G2*F2*1000 -> 2.2122738 | I2: 405.8 | J2: =I2*F2*1000 -> 2.0955666 | K2: Volumen to FQA (3) | L2: Dry mass to FQA (3)
A3: W1F | B3: 0.0926 | C3: =AVERAGE(0.2974, 0.295) -> 0.2962 | D3: =C3*B4 -> 0.02393296 | E3: 5001.4 | F3: =D3/E3 -> 4.7852521e-06 | G3: 456.1 | H3: =G3*F3*1000 -> 2.1825535 | I3: 437.7 | J3: =I3*F3*1000 -> 2.0945049
A4: W2F | B4: 0.0808 | C4: =AVERAGE(0.2998, 0.2965, 0.3007) -> 0.299 | D4: =C4*B5 -> 0.0218868 | E4: 5002.9 | F4: =D4/E4 -> 4.3748226e-06 | G4: 600 | H4: =G4*F4*1000 -> 2.6248936 | I4: 454 | J4: =I4*F4*1000 -> 1.9861695
A5: W3F | B5: 0.0732 | C5: 0.281 | D5: =C5*B6 -> 0.0200915 | E5: 4999.7 | F5: =D5/E5 -> 4.0185411e-06 | G5: 601.5 | H5: =G5*F5*1000 -> 2.4171525 | I5: 605 | J5: =I5*F5*1000 -> 2.4312174
A6: W1N | B6: 0.0715 | C6: 0.309 | D6: =C6*B7 -> 0.022557 | E6: 5000.3 | F6: =D6/E6 -> 4.5111293e-06 | G6: 602.3 | H6: =G6*F6*1000 -> 2.7170532 | I6: 601.1 | J6: =I6*F6*1000 -> 2.7116398
A7: W2N | B7: 0.073 | C7: 0.2778 | D7: =C7*B8 -> 0.02350188 | E7: 5020.5 | F7: =D7/E7 -> 4.6811831e-06 | G7: 346 | H7: =G7*F7*1000 -> 1.6196894 | I7: 366 | J7: =I7*F7*1000 -> 1.713313
A8: W3N | B8: 0.0846 | C8: 0.3051 | D8: =C8*B9 -> 0.02337066 | E8: 5009.8 | F8: =D8/E8 -> 4.6649886e-06 | G8: 394.1 | H8: =G8*F8*1000 -> 1.838472 | I8: 364.2 | J8: =I8*F8*1000 -> 1.6989889
A9: E1F | B9: 0.0766 | C9: 0.2996 | D9: =C9*B10 -> 0.02252992 | E9: 5013.2 | F9: =D9/E9 -> 4.4941195e-06 | G9: 306.7 | H9: =G9*F9*1000 -> 1.3783465 | I9: 303.6 | J9: =I9*F9*1000 -> 1.3644147
A10: E2F | B10: 0.0752 | C10: 0.3052 | D10: =C10*B11 -> 0.0224322 | E10: 5003.8 | F10: =D10/E10 -> 4.4830329e-06 | G10: 330.5 | H10: =G10*F10*1000 -> 1.4816424 | I10: 313.9 | J10: =I10*F10*1000 -> 1.407224
A11: E3F | B11: 0.0735 | C11: 0.2812 | D11: =C11*B12 -> 0.0258704 | E11: 4995.8 | F11: =D11/E11 -> 5.1784299e-06 | G11: 411 | H11: =G11*F11*1000 -> 2.1283347 | I11: 407.9 | J11: =I11*F11*1000 -> 2.1122815
A12: E1N | B12: 0.092 | C12: 0.2922 | D12: =C12*B13 -> 0.02343444 | E12: 5001.4 | F12: =D12/E12 -> 4.685576e-06 | G12: 368.9 | H12: =G12*F12*1000 -> 1.728509 | I12: 318.7 | J12: =I12*F12*1000 -> 1.4932931
A13: E2N | B13: 0.0802 | C13: 0.2959 | D13: =C13*B14 -> 0.02390872 | E13: 4995.1 | F13: =D13/E13 -> 4.7864347e-06 | G13: 601.4 | H13: =G13*F13*1000 -> 2.8785618 | I13: 469.2 | J13: =I13*F13*1000 -> 2.2457952
A14: E3N | B14: 0.0808 | K14: 455.4 | L14: =K14*F13*1000 -> 2.1797424

Sheet Handsheet_properties
A1: ID | B1: weight | C1: thickness | D1: Biomass
A2: E3AF3 | B2: 1.3584 | C2: 110 | D2: E
A3: E3AF1 | B3: 1.3583 | C3: 112 | D3: E
A4: E3AN1 | B4: 1.2877 | C4: 100 | D4: E
A5: E2AN4 | B5: 1.1862 | C5: 95 | D5: E
A6: E2AN1 | B6: 1.2096 | C6: 93 | D6: E
A7: E2AF3 | B7: 1.3012 | C7: 107 | D7: E
A8: E3AF2 | B8: 1.3725 | C8: 111 | D8: E
A9: E1AN3 | B9: 1.2865 | C9: 102 | D9: E
A10: E1AN2 | B10: 1.293 | C10: 99 | D10: E
A11: E2AN3 | B11: 1.2054 | C11: 96 | D11: E
A12: E2AN2 | B12: 1.2114 | C12: 97 | D12: E
A13: E3AN4 | B13: 1.3226 | C13: 102 | D13: E
... A142: W3F51 | B142: 1.2906 | C142: 102 | D142: W

Sheet Freeness
A1: Code | B1: fines | C1: ID1 | D1: u_freeness | E1: Temperature | F1: OD_mass_freeness_hs | G1: Consistency | H1: freeness
A2: W1 | B2: Y | C2: W1F | D2: 500 | E2: 28 | F2: 2.967 | G2: =F2/1000 -> 0.002967 | H2: 445
A3: W1 | B3: N | C3: W1N | D3: 600 | E3: 29 | F3: 2.97 | G3: =F3/1000 -> 0.00297 | H3: 554
A4: W2 | B4: Y | C4: W2F | D4: 510 | E4: 28 | F4: 3.08 | G4: =F4/1000 -> 0.00308 | H4: 464
A5: W2 | B5: N | C5: W2N | D5: 620 | E5: 30 | F5: 2.767 | G5: =F5/1000 -> 0.002767 | H5: 561
A6: W3 | B6: Y | C6: W3F | D6: 500 | E6: 28 | F6: 3.067 | G6: =F6/1000 -> 0.003067 | H6: 453
A7: W3 | B7: N | C7: W3N | D7: 600 | E7: 29 | F7: 2.994 | G7: =F7/1000 -> 0.002994 | H7: 554
A8: E1 | B8: Y | C8: E1F | D8: 600 | E8: 28 | F8: 3.094 | G8: =F8/1000 -> 0.003094 | H8: 564
A9: E1 | B9: N | C9: E1N | D9: 670 | E9: 30 | F9: 2.872 | G9: =F9/1000 -> 0.002872 | H9: 628
A10: E2 | B10: Y | C10: E2F | D10: 610 | E10: 30 | F10: 3.075 | G10: =F10/1000 -> 0.003075 | H10: 569
A11: E2 | B11: N | C11: E2N | D11: 690 | E11: 31 | F11: 2.706 | G11: =F11/1000 -> 0.002706 | H11: 647
A12: E3 | B12: Y | C12: E3F | D12: 630 | E12: 30 | F12: 3.143 | G12: =F12/1000 -> 0.003143 | H12: 599
A13: E3 | B13: N | C13: E3N | D13: 685 | E13: 30 | F13: 2.805 | G13: =F13/1000 -> 0.002805 | H13: 645
